2023-10-21 23:51:21,509 - aiogram - INFO - Bot: Helper [@toppgrouppbot]
2023-10-21 23:51:21,640 - aiogram - WARNING - Updates were skipped successfully.
2023-10-21 23:51:21,647 - aiogram.dispatcher.dispatcher - INFO - Start polling.
2023-10-21 23:51:23,317 - tg_bot.functions.wrapping.wrapping - CRITICAL - crit
2023-10-21 23:51:50,659 - aiogram - INFO - Bot: Helper [@toppgrouppbot]
2023-10-21 23:51:50,797 - aiogram - WARNING - Updates were skipped successfully.
2023-10-21 23:51:50,803 - aiogram.dispatcher.dispatcher - INFO - Start polling.
2023-10-21 23:51:55,315 - tg_bot.functions.wrapping.wrapping - ERROR - crit
2023-10-21 23:56:29,016 - aiogram - INFO - Bot: Helper [@toppgrouppbot]
2023-10-21 23:56:29,165 - aiogram - WARNING - Updates were skipped successfully.
2023-10-21 23:56:29,171 - aiogram.dispatcher.dispatcher - INFO - Start polling.
2023-10-22 00:02:58,464 - aiogram - INFO - Bot: Helper [@toppgrouppbot]
2023-10-22 00:02:58,620 - aiogram - WARNING - Updates were skipped successfully.
2023-10-22 00:02:58,626 - aiogram.dispatcher.dispatcher - INFO - Start polling.
2023-10-22 00:16:34,155 - aiogram - INFO - Bot: Helper [@toppgrouppbot]
2023-10-22 00:16:34,292 - aiogram - WARNING - Updates were skipped successfully.
2023-10-22 00:17:08,319 - aiogram - INFO - Bot: Helper [@toppgrouppbot]
2023-10-22 00:17:08,476 - aiogram - WARNING - Updates were skipped successfully.
2023-10-22 00:17:10,650 - aiogram.dispatcher.dispatcher - INFO - Start polling.
2023-10-22 00:17:16,107 - aiogram.dispatcher.dispatcher - ERROR - Cause exception while getting updates.
Traceback (most recent call last):
  File "C:\Users\Dmitry\AppData\Local\Programs\Python\Python39\lib\site-packages\aiogram\dispatcher\dispatcher.py", line 381, in start_polling
    updates = await self.bot.get_updates(
  File "C:\Users\Dmitry\AppData\Local\Programs\Python\Python39\lib\site-packages\aiogram\bot\bot.py", line 110, in get_updates
    result = await self.request(api.Methods.GET_UPDATES, payload)
  File "C:\Users\Dmitry\AppData\Local\Programs\Python\Python39\lib\site-packages\aiogram\bot\base.py", line 236, in request
    return await api.make_request(await self.get_session(), self.server, self.__token, method, data, files,
  File "C:\Users\Dmitry\AppData\Local\Programs\Python\Python39\lib\site-packages\aiogram\bot\api.py", line 140, in make_request
    return check_result(method, response.content_type, response.status, await response.text())
  File "C:\Users\Dmitry\AppData\Local\Programs\Python\Python39\lib\site-packages\aiogram\bot\api.py", line 119, in check_result
    exceptions.ConflictError.detect(description)
  File "C:\Users\Dmitry\AppData\Local\Programs\Python\Python39\lib\site-packages\aiogram\utils\exceptions.py", line 140, in detect
    raise err(cls.text or description)
aiogram.utils.exceptions.TerminatedByOtherGetUpdates: Terminated by other getupdates request; make sure that only one bot instance is running
2023-10-22 00:17:44,635 - aiogram - INFO - Bot: Helper [@toppgrouppbot]
2023-10-22 00:17:44,806 - aiogram - WARNING - Updates were skipped successfully.
2023-10-22 00:18:21,331 - aiogram - INFO - Bot: Helper [@toppgrouppbot]
2023-10-22 00:18:21,477 - aiogram - WARNING - Updates were skipped successfully.
2023-10-22 00:18:22,602 - vk_bot.bot.main - INFO - SUCCESS CONNECTION (vk_bot)
2023-10-22 00:18:24,803 - aiogram.dispatcher.dispatcher - INFO - Start polling.
2023-10-22 00:18:30,007 - aiogram.dispatcher.dispatcher - ERROR - Cause exception while getting updates.
Traceback (most recent call last):
  File "C:\Users\Dmitry\AppData\Local\Programs\Python\Python39\lib\site-packages\aiogram\dispatcher\dispatcher.py", line 381, in start_polling
    updates = await self.bot.get_updates(
  File "C:\Users\Dmitry\AppData\Local\Programs\Python\Python39\lib\site-packages\aiogram\bot\bot.py", line 110, in get_updates
    result = await self.request(api.Methods.GET_UPDATES, payload)
  File "C:\Users\Dmitry\AppData\Local\Programs\Python\Python39\lib\site-packages\aiogram\bot\base.py", line 236, in request
    return await api.make_request(await self.get_session(), self.server, self.__token, method, data, files,
  File "C:\Users\Dmitry\AppData\Local\Programs\Python\Python39\lib\site-packages\aiogram\bot\api.py", line 140, in make_request
    return check_result(method, response.content_type, response.status, await response.text())
  File "C:\Users\Dmitry\AppData\Local\Programs\Python\Python39\lib\site-packages\aiogram\bot\api.py", line 119, in check_result
    exceptions.ConflictError.detect(description)
  File "C:\Users\Dmitry\AppData\Local\Programs\Python\Python39\lib\site-packages\aiogram\utils\exceptions.py", line 140, in detect
    raise err(cls.text or description)
aiogram.utils.exceptions.TerminatedByOtherGetUpdates: Terminated by other getupdates request; make sure that only one bot instance is running
2023-10-22 00:18:40,154 - aiogram.dispatcher.dispatcher - ERROR - Cause exception while getting updates.
Traceback (most recent call last):
  File "C:\Users\Dmitry\AppData\Local\Programs\Python\Python39\lib\site-packages\aiogram\dispatcher\dispatcher.py", line 381, in start_polling
    updates = await self.bot.get_updates(
  File "C:\Users\Dmitry\AppData\Local\Programs\Python\Python39\lib\site-packages\aiogram\bot\bot.py", line 110, in get_updates
    result = await self.request(api.Methods.GET_UPDATES, payload)
  File "C:\Users\Dmitry\AppData\Local\Programs\Python\Python39\lib\site-packages\aiogram\bot\base.py", line 236, in request
    return await api.make_request(await self.get_session(), self.server, self.__token, method, data, files,
  File "C:\Users\Dmitry\AppData\Local\Programs\Python\Python39\lib\site-packages\aiogram\bot\api.py", line 140, in make_request
    return check_result(method, response.content_type, response.status, await response.text())
  File "C:\Users\Dmitry\AppData\Local\Programs\Python\Python39\lib\site-packages\aiogram\bot\api.py", line 119, in check_result
    exceptions.ConflictError.detect(description)
  File "C:\Users\Dmitry\AppData\Local\Programs\Python\Python39\lib\site-packages\aiogram\utils\exceptions.py", line 140, in detect
    raise err(cls.text or description)
aiogram.utils.exceptions.TerminatedByOtherGetUpdates: Terminated by other getupdates request; make sure that only one bot instance is running
2023-10-22 00:18:50,292 - aiogram.dispatcher.dispatcher - ERROR - Cause exception while getting updates.
Traceback (most recent call last):
  File "C:\Users\Dmitry\AppData\Local\Programs\Python\Python39\lib\site-packages\aiogram\dispatcher\dispatcher.py", line 381, in start_polling
    updates = await self.bot.get_updates(
  File "C:\Users\Dmitry\AppData\Local\Programs\Python\Python39\lib\site-packages\aiogram\bot\bot.py", line 110, in get_updates
    result = await self.request(api.Methods.GET_UPDATES, payload)
  File "C:\Users\Dmitry\AppData\Local\Programs\Python\Python39\lib\site-packages\aiogram\bot\base.py", line 236, in request
    return await api.make_request(await self.get_session(), self.server, self.__token, method, data, files,
  File "C:\Users\Dmitry\AppData\Local\Programs\Python\Python39\lib\site-packages\aiogram\bot\api.py", line 140, in make_request
    return check_result(method, response.content_type, response.status, await response.text())
  File "C:\Users\Dmitry\AppData\Local\Programs\Python\Python39\lib\site-packages\aiogram\bot\api.py", line 119, in check_result
    exceptions.ConflictError.detect(description)
  File "C:\Users\Dmitry\AppData\Local\Programs\Python\Python39\lib\site-packages\aiogram\utils\exceptions.py", line 140, in detect
    raise err(cls.text or description)
aiogram.utils.exceptions.TerminatedByOtherGetUpdates: Terminated by other getupdates request; make sure that only one bot instance is running
2023-10-22 00:18:55,663 - aiogram - INFO - Bot: Helper [@toppgrouppbot]
2023-10-22 00:18:55,447 - vk_bot.bot.main - ERROR - SUCCESS CONNECTION (vk_bot)
2023-10-22 00:18:55,799 - aiogram - WARNING - Updates were skipped successfully.
2023-10-22 00:18:55,807 - aiogram.dispatcher.dispatcher - INFO - Start polling.
2023-10-22 00:19:01,018 - aiogram.dispatcher.dispatcher - ERROR - Cause exception while getting updates.
Traceback (most recent call last):
  File "C:\Users\Dmitry\AppData\Local\Programs\Python\Python39\lib\site-packages\aiogram\dispatcher\dispatcher.py", line 381, in start_polling
    updates = await self.bot.get_updates(
  File "C:\Users\Dmitry\AppData\Local\Programs\Python\Python39\lib\site-packages\aiogram\bot\bot.py", line 110, in get_updates
    result = await self.request(api.Methods.GET_UPDATES, payload)
  File "C:\Users\Dmitry\AppData\Local\Programs\Python\Python39\lib\site-packages\aiogram\bot\base.py", line 236, in request
    return await api.make_request(await self.get_session(), self.server, self.__token, method, data, files,
  File "C:\Users\Dmitry\AppData\Local\Programs\Python\Python39\lib\site-packages\aiogram\bot\api.py", line 140, in make_request
    return check_result(method, response.content_type, response.status, await response.text())
  File "C:\Users\Dmitry\AppData\Local\Programs\Python\Python39\lib\site-packages\aiogram\bot\api.py", line 119, in check_result
    exceptions.ConflictError.detect(description)
  File "C:\Users\Dmitry\AppData\Local\Programs\Python\Python39\lib\site-packages\aiogram\utils\exceptions.py", line 140, in detect
    raise err(cls.text or description)
aiogram.utils.exceptions.TerminatedByOtherGetUpdates: Terminated by other getupdates request; make sure that only one bot instance is running
2023-10-22 00:19:11,148 - aiogram.dispatcher.dispatcher - ERROR - Cause exception while getting updates.
Traceback (most recent call last):
  File "C:\Users\Dmitry\AppData\Local\Programs\Python\Python39\lib\site-packages\aiogram\dispatcher\dispatcher.py", line 381, in start_polling
    updates = await self.bot.get_updates(
  File "C:\Users\Dmitry\AppData\Local\Programs\Python\Python39\lib\site-packages\aiogram\bot\bot.py", line 110, in get_updates
    result = await self.request(api.Methods.GET_UPDATES, payload)
  File "C:\Users\Dmitry\AppData\Local\Programs\Python\Python39\lib\site-packages\aiogram\bot\base.py", line 236, in request
    return await api.make_request(await self.get_session(), self.server, self.__token, method, data, files,
  File "C:\Users\Dmitry\AppData\Local\Programs\Python\Python39\lib\site-packages\aiogram\bot\api.py", line 140, in make_request
    return check_result(method, response.content_type, response.status, await response.text())
  File "C:\Users\Dmitry\AppData\Local\Programs\Python\Python39\lib\site-packages\aiogram\bot\api.py", line 119, in check_result
    exceptions.ConflictError.detect(description)
  File "C:\Users\Dmitry\AppData\Local\Programs\Python\Python39\lib\site-packages\aiogram\utils\exceptions.py", line 140, in detect
    raise err(cls.text or description)
aiogram.utils.exceptions.TerminatedByOtherGetUpdates: Terminated by other getupdates request; make sure that only one bot instance is running
2023-10-22 00:19:21,288 - aiogram.dispatcher.dispatcher - ERROR - Cause exception while getting updates.
Traceback (most recent call last):
  File "C:\Users\Dmitry\AppData\Local\Programs\Python\Python39\lib\site-packages\aiogram\dispatcher\dispatcher.py", line 381, in start_polling
    updates = await self.bot.get_updates(
  File "C:\Users\Dmitry\AppData\Local\Programs\Python\Python39\lib\site-packages\aiogram\bot\bot.py", line 110, in get_updates
    result = await self.request(api.Methods.GET_UPDATES, payload)
  File "C:\Users\Dmitry\AppData\Local\Programs\Python\Python39\lib\site-packages\aiogram\bot\base.py", line 236, in request
    return await api.make_request(await self.get_session(), self.server, self.__token, method, data, files,
  File "C:\Users\Dmitry\AppData\Local\Programs\Python\Python39\lib\site-packages\aiogram\bot\api.py", line 140, in make_request
    return check_result(method, response.content_type, response.status, await response.text())
  File "C:\Users\Dmitry\AppData\Local\Programs\Python\Python39\lib\site-packages\aiogram\bot\api.py", line 119, in check_result
    exceptions.ConflictError.detect(description)
  File "C:\Users\Dmitry\AppData\Local\Programs\Python\Python39\lib\site-packages\aiogram\utils\exceptions.py", line 140, in detect
    raise err(cls.text or description)
aiogram.utils.exceptions.TerminatedByOtherGetUpdates: Terminated by other getupdates request; make sure that only one bot instance is running
2023-10-22 00:19:31,440 - aiogram.dispatcher.dispatcher - ERROR - Cause exception while getting updates.
Traceback (most recent call last):
  File "C:\Users\Dmitry\AppData\Local\Programs\Python\Python39\lib\site-packages\aiogram\dispatcher\dispatcher.py", line 381, in start_polling
    updates = await self.bot.get_updates(
  File "C:\Users\Dmitry\AppData\Local\Programs\Python\Python39\lib\site-packages\aiogram\bot\bot.py", line 110, in get_updates
    result = await self.request(api.Methods.GET_UPDATES, payload)
  File "C:\Users\Dmitry\AppData\Local\Programs\Python\Python39\lib\site-packages\aiogram\bot\base.py", line 236, in request
    return await api.make_request(await self.get_session(), self.server, self.__token, method, data, files,
  File "C:\Users\Dmitry\AppData\Local\Programs\Python\Python39\lib\site-packages\aiogram\bot\api.py", line 140, in make_request
    return check_result(method, response.content_type, response.status, await response.text())
  File "C:\Users\Dmitry\AppData\Local\Programs\Python\Python39\lib\site-packages\aiogram\bot\api.py", line 119, in check_result
    exceptions.ConflictError.detect(description)
  File "C:\Users\Dmitry\AppData\Local\Programs\Python\Python39\lib\site-packages\aiogram\utils\exceptions.py", line 140, in detect
    raise err(cls.text or description)
aiogram.utils.exceptions.TerminatedByOtherGetUpdates: Terminated by other getupdates request; make sure that only one bot instance is running
2023-10-22 00:19:41,577 - aiogram.dispatcher.dispatcher - ERROR - Cause exception while getting updates.
Traceback (most recent call last):
  File "C:\Users\Dmitry\AppData\Local\Programs\Python\Python39\lib\site-packages\aiogram\dispatcher\dispatcher.py", line 381, in start_polling
    updates = await self.bot.get_updates(
  File "C:\Users\Dmitry\AppData\Local\Programs\Python\Python39\lib\site-packages\aiogram\bot\bot.py", line 110, in get_updates
    result = await self.request(api.Methods.GET_UPDATES, payload)
  File "C:\Users\Dmitry\AppData\Local\Programs\Python\Python39\lib\site-packages\aiogram\bot\base.py", line 236, in request
    return await api.make_request(await self.get_session(), self.server, self.__token, method, data, files,
  File "C:\Users\Dmitry\AppData\Local\Programs\Python\Python39\lib\site-packages\aiogram\bot\api.py", line 140, in make_request
    return check_result(method, response.content_type, response.status, await response.text())
  File "C:\Users\Dmitry\AppData\Local\Programs\Python\Python39\lib\site-packages\aiogram\bot\api.py", line 119, in check_result
    exceptions.ConflictError.detect(description)
  File "C:\Users\Dmitry\AppData\Local\Programs\Python\Python39\lib\site-packages\aiogram\utils\exceptions.py", line 140, in detect
    raise err(cls.text or description)
aiogram.utils.exceptions.TerminatedByOtherGetUpdates: Terminated by other getupdates request; make sure that only one bot instance is running
2023-10-22 00:19:51,706 - aiogram.dispatcher.dispatcher - ERROR - Cause exception while getting updates.
Traceback (most recent call last):
  File "C:\Users\Dmitry\AppData\Local\Programs\Python\Python39\lib\site-packages\aiogram\dispatcher\dispatcher.py", line 381, in start_polling
    updates = await self.bot.get_updates(
  File "C:\Users\Dmitry\AppData\Local\Programs\Python\Python39\lib\site-packages\aiogram\bot\bot.py", line 110, in get_updates
    result = await self.request(api.Methods.GET_UPDATES, payload)
  File "C:\Users\Dmitry\AppData\Local\Programs\Python\Python39\lib\site-packages\aiogram\bot\base.py", line 236, in request
    return await api.make_request(await self.get_session(), self.server, self.__token, method, data, files,
  File "C:\Users\Dmitry\AppData\Local\Programs\Python\Python39\lib\site-packages\aiogram\bot\api.py", line 140, in make_request
    return check_result(method, response.content_type, response.status, await response.text())
  File "C:\Users\Dmitry\AppData\Local\Programs\Python\Python39\lib\site-packages\aiogram\bot\api.py", line 119, in check_result
    exceptions.ConflictError.detect(description)
  File "C:\Users\Dmitry\AppData\Local\Programs\Python\Python39\lib\site-packages\aiogram\utils\exceptions.py", line 140, in detect
    raise err(cls.text or description)
aiogram.utils.exceptions.TerminatedByOtherGetUpdates: Terminated by other getupdates request; make sure that only one bot instance is running
2023-10-22 00:20:01,845 - aiogram.dispatcher.dispatcher - ERROR - Cause exception while getting updates.
Traceback (most recent call last):
  File "C:\Users\Dmitry\AppData\Local\Programs\Python\Python39\lib\site-packages\aiogram\dispatcher\dispatcher.py", line 381, in start_polling
    updates = await self.bot.get_updates(
  File "C:\Users\Dmitry\AppData\Local\Programs\Python\Python39\lib\site-packages\aiogram\bot\bot.py", line 110, in get_updates
    result = await self.request(api.Methods.GET_UPDATES, payload)
  File "C:\Users\Dmitry\AppData\Local\Programs\Python\Python39\lib\site-packages\aiogram\bot\base.py", line 236, in request
    return await api.make_request(await self.get_session(), self.server, self.__token, method, data, files,
  File "C:\Users\Dmitry\AppData\Local\Programs\Python\Python39\lib\site-packages\aiogram\bot\api.py", line 140, in make_request
    return check_result(method, response.content_type, response.status, await response.text())
  File "C:\Users\Dmitry\AppData\Local\Programs\Python\Python39\lib\site-packages\aiogram\bot\api.py", line 119, in check_result
    exceptions.ConflictError.detect(description)
  File "C:\Users\Dmitry\AppData\Local\Programs\Python\Python39\lib\site-packages\aiogram\utils\exceptions.py", line 140, in detect
    raise err(cls.text or description)
aiogram.utils.exceptions.TerminatedByOtherGetUpdates: Terminated by other getupdates request; make sure that only one bot instance is running
2023-10-22 00:20:19,868 - aiogram.dispatcher.dispatcher - ERROR - Cause exception while getting updates.
Traceback (most recent call last):
  File "C:\Users\Dmitry\AppData\Local\Programs\Python\Python39\lib\site-packages\aiogram\dispatcher\dispatcher.py", line 381, in start_polling
    updates = await self.bot.get_updates(
  File "C:\Users\Dmitry\AppData\Local\Programs\Python\Python39\lib\site-packages\aiogram\bot\bot.py", line 110, in get_updates
    result = await self.request(api.Methods.GET_UPDATES, payload)
  File "C:\Users\Dmitry\AppData\Local\Programs\Python\Python39\lib\site-packages\aiogram\bot\base.py", line 236, in request
    return await api.make_request(await self.get_session(), self.server, self.__token, method, data, files,
  File "C:\Users\Dmitry\AppData\Local\Programs\Python\Python39\lib\site-packages\aiogram\bot\api.py", line 140, in make_request
    return check_result(method, response.content_type, response.status, await response.text())
  File "C:\Users\Dmitry\AppData\Local\Programs\Python\Python39\lib\site-packages\aiogram\bot\api.py", line 119, in check_result
    exceptions.ConflictError.detect(description)
  File "C:\Users\Dmitry\AppData\Local\Programs\Python\Python39\lib\site-packages\aiogram\utils\exceptions.py", line 140, in detect
    raise err(cls.text or description)
aiogram.utils.exceptions.TerminatedByOtherGetUpdates: Terminated by other getupdates request; make sure that only one bot instance is running
2023-10-22 00:20:30,029 - aiogram.dispatcher.dispatcher - ERROR - Cause exception while getting updates.
Traceback (most recent call last):
  File "C:\Users\Dmitry\AppData\Local\Programs\Python\Python39\lib\site-packages\aiogram\dispatcher\dispatcher.py", line 381, in start_polling
    updates = await self.bot.get_updates(
  File "C:\Users\Dmitry\AppData\Local\Programs\Python\Python39\lib\site-packages\aiogram\bot\bot.py", line 110, in get_updates
    result = await self.request(api.Methods.GET_UPDATES, payload)
  File "C:\Users\Dmitry\AppData\Local\Programs\Python\Python39\lib\site-packages\aiogram\bot\base.py", line 236, in request
    return await api.make_request(await self.get_session(), self.server, self.__token, method, data, files,
  File "C:\Users\Dmitry\AppData\Local\Programs\Python\Python39\lib\site-packages\aiogram\bot\api.py", line 140, in make_request
    return check_result(method, response.content_type, response.status, await response.text())
  File "C:\Users\Dmitry\AppData\Local\Programs\Python\Python39\lib\site-packages\aiogram\bot\api.py", line 119, in check_result
    exceptions.ConflictError.detect(description)
  File "C:\Users\Dmitry\AppData\Local\Programs\Python\Python39\lib\site-packages\aiogram\utils\exceptions.py", line 140, in detect
    raise err(cls.text or description)
aiogram.utils.exceptions.TerminatedByOtherGetUpdates: Terminated by other getupdates request; make sure that only one bot instance is running
2023-10-22 00:20:40,203 - aiogram.dispatcher.dispatcher - ERROR - Cause exception while getting updates.
Traceback (most recent call last):
  File "C:\Users\Dmitry\AppData\Local\Programs\Python\Python39\lib\site-packages\aiogram\dispatcher\dispatcher.py", line 381, in start_polling
    updates = await self.bot.get_updates(
  File "C:\Users\Dmitry\AppData\Local\Programs\Python\Python39\lib\site-packages\aiogram\bot\bot.py", line 110, in get_updates
    result = await self.request(api.Methods.GET_UPDATES, payload)
  File "C:\Users\Dmitry\AppData\Local\Programs\Python\Python39\lib\site-packages\aiogram\bot\base.py", line 236, in request
    return await api.make_request(await self.get_session(), self.server, self.__token, method, data, files,
  File "C:\Users\Dmitry\AppData\Local\Programs\Python\Python39\lib\site-packages\aiogram\bot\api.py", line 140, in make_request
    return check_result(method, response.content_type, response.status, await response.text())
  File "C:\Users\Dmitry\AppData\Local\Programs\Python\Python39\lib\site-packages\aiogram\bot\api.py", line 119, in check_result
    exceptions.ConflictError.detect(description)
  File "C:\Users\Dmitry\AppData\Local\Programs\Python\Python39\lib\site-packages\aiogram\utils\exceptions.py", line 140, in detect
    raise err(cls.text or description)
aiogram.utils.exceptions.TerminatedByOtherGetUpdates: Terminated by other getupdates request; make sure that only one bot instance is running
2023-10-22 00:20:50,350 - aiogram.dispatcher.dispatcher - ERROR - Cause exception while getting updates.
Traceback (most recent call last):
  File "C:\Users\Dmitry\AppData\Local\Programs\Python\Python39\lib\site-packages\aiogram\dispatcher\dispatcher.py", line 381, in start_polling
    updates = await self.bot.get_updates(
  File "C:\Users\Dmitry\AppData\Local\Programs\Python\Python39\lib\site-packages\aiogram\bot\bot.py", line 110, in get_updates
    result = await self.request(api.Methods.GET_UPDATES, payload)
  File "C:\Users\Dmitry\AppData\Local\Programs\Python\Python39\lib\site-packages\aiogram\bot\base.py", line 236, in request
    return await api.make_request(await self.get_session(), self.server, self.__token, method, data, files,
  File "C:\Users\Dmitry\AppData\Local\Programs\Python\Python39\lib\site-packages\aiogram\bot\api.py", line 140, in make_request
    return check_result(method, response.content_type, response.status, await response.text())
  File "C:\Users\Dmitry\AppData\Local\Programs\Python\Python39\lib\site-packages\aiogram\bot\api.py", line 119, in check_result
    exceptions.ConflictError.detect(description)
  File "C:\Users\Dmitry\AppData\Local\Programs\Python\Python39\lib\site-packages\aiogram\utils\exceptions.py", line 140, in detect
    raise err(cls.text or description)
aiogram.utils.exceptions.TerminatedByOtherGetUpdates: Terminated by other getupdates request; make sure that only one bot instance is running
2023-10-22 00:21:00,490 - aiogram.dispatcher.dispatcher - ERROR - Cause exception while getting updates.
Traceback (most recent call last):
  File "C:\Users\Dmitry\AppData\Local\Programs\Python\Python39\lib\site-packages\aiogram\dispatcher\dispatcher.py", line 381, in start_polling
    updates = await self.bot.get_updates(
  File "C:\Users\Dmitry\AppData\Local\Programs\Python\Python39\lib\site-packages\aiogram\bot\bot.py", line 110, in get_updates
    result = await self.request(api.Methods.GET_UPDATES, payload)
  File "C:\Users\Dmitry\AppData\Local\Programs\Python\Python39\lib\site-packages\aiogram\bot\base.py", line 236, in request
    return await api.make_request(await self.get_session(), self.server, self.__token, method, data, files,
  File "C:\Users\Dmitry\AppData\Local\Programs\Python\Python39\lib\site-packages\aiogram\bot\api.py", line 140, in make_request
    return check_result(method, response.content_type, response.status, await response.text())
  File "C:\Users\Dmitry\AppData\Local\Programs\Python\Python39\lib\site-packages\aiogram\bot\api.py", line 119, in check_result
    exceptions.ConflictError.detect(description)
  File "C:\Users\Dmitry\AppData\Local\Programs\Python\Python39\lib\site-packages\aiogram\utils\exceptions.py", line 140, in detect
    raise err(cls.text or description)
aiogram.utils.exceptions.TerminatedByOtherGetUpdates: Terminated by other getupdates request; make sure that only one bot instance is running
2023-10-22 00:21:10,625 - aiogram.dispatcher.dispatcher - ERROR - Cause exception while getting updates.
Traceback (most recent call last):
  File "C:\Users\Dmitry\AppData\Local\Programs\Python\Python39\lib\site-packages\aiogram\dispatcher\dispatcher.py", line 381, in start_polling
    updates = await self.bot.get_updates(
  File "C:\Users\Dmitry\AppData\Local\Programs\Python\Python39\lib\site-packages\aiogram\bot\bot.py", line 110, in get_updates
    result = await self.request(api.Methods.GET_UPDATES, payload)
  File "C:\Users\Dmitry\AppData\Local\Programs\Python\Python39\lib\site-packages\aiogram\bot\base.py", line 236, in request
    return await api.make_request(await self.get_session(), self.server, self.__token, method, data, files,
  File "C:\Users\Dmitry\AppData\Local\Programs\Python\Python39\lib\site-packages\aiogram\bot\api.py", line 140, in make_request
    return check_result(method, response.content_type, response.status, await response.text())
  File "C:\Users\Dmitry\AppData\Local\Programs\Python\Python39\lib\site-packages\aiogram\bot\api.py", line 119, in check_result
    exceptions.ConflictError.detect(description)
  File "C:\Users\Dmitry\AppData\Local\Programs\Python\Python39\lib\site-packages\aiogram\utils\exceptions.py", line 140, in detect
    raise err(cls.text or description)
aiogram.utils.exceptions.TerminatedByOtherGetUpdates: Terminated by other getupdates request; make sure that only one bot instance is running
2023-10-22 00:21:20,773 - aiogram.dispatcher.dispatcher - ERROR - Cause exception while getting updates.
Traceback (most recent call last):
  File "C:\Users\Dmitry\AppData\Local\Programs\Python\Python39\lib\site-packages\aiogram\dispatcher\dispatcher.py", line 381, in start_polling
    updates = await self.bot.get_updates(
  File "C:\Users\Dmitry\AppData\Local\Programs\Python\Python39\lib\site-packages\aiogram\bot\bot.py", line 110, in get_updates
    result = await self.request(api.Methods.GET_UPDATES, payload)
  File "C:\Users\Dmitry\AppData\Local\Programs\Python\Python39\lib\site-packages\aiogram\bot\base.py", line 236, in request
    return await api.make_request(await self.get_session(), self.server, self.__token, method, data, files,
  File "C:\Users\Dmitry\AppData\Local\Programs\Python\Python39\lib\site-packages\aiogram\bot\api.py", line 140, in make_request
    return check_result(method, response.content_type, response.status, await response.text())
  File "C:\Users\Dmitry\AppData\Local\Programs\Python\Python39\lib\site-packages\aiogram\bot\api.py", line 119, in check_result
    exceptions.ConflictError.detect(description)
  File "C:\Users\Dmitry\AppData\Local\Programs\Python\Python39\lib\site-packages\aiogram\utils\exceptions.py", line 140, in detect
    raise err(cls.text or description)
aiogram.utils.exceptions.TerminatedByOtherGetUpdates: Terminated by other getupdates request; make sure that only one bot instance is running
2023-10-22 00:21:30,921 - aiogram.dispatcher.dispatcher - ERROR - Cause exception while getting updates.
Traceback (most recent call last):
  File "C:\Users\Dmitry\AppData\Local\Programs\Python\Python39\lib\site-packages\aiogram\dispatcher\dispatcher.py", line 381, in start_polling
    updates = await self.bot.get_updates(
  File "C:\Users\Dmitry\AppData\Local\Programs\Python\Python39\lib\site-packages\aiogram\bot\bot.py", line 110, in get_updates
    result = await self.request(api.Methods.GET_UPDATES, payload)
  File "C:\Users\Dmitry\AppData\Local\Programs\Python\Python39\lib\site-packages\aiogram\bot\base.py", line 236, in request
    return await api.make_request(await self.get_session(), self.server, self.__token, method, data, files,
  File "C:\Users\Dmitry\AppData\Local\Programs\Python\Python39\lib\site-packages\aiogram\bot\api.py", line 140, in make_request
    return check_result(method, response.content_type, response.status, await response.text())
  File "C:\Users\Dmitry\AppData\Local\Programs\Python\Python39\lib\site-packages\aiogram\bot\api.py", line 119, in check_result
    exceptions.ConflictError.detect(description)
  File "C:\Users\Dmitry\AppData\Local\Programs\Python\Python39\lib\site-packages\aiogram\utils\exceptions.py", line 140, in detect
    raise err(cls.text or description)
aiogram.utils.exceptions.TerminatedByOtherGetUpdates: Terminated by other getupdates request; make sure that only one bot instance is running
2023-10-22 00:21:41,084 - aiogram.dispatcher.dispatcher - ERROR - Cause exception while getting updates.
Traceback (most recent call last):
  File "C:\Users\Dmitry\AppData\Local\Programs\Python\Python39\lib\site-packages\aiogram\dispatcher\dispatcher.py", line 381, in start_polling
    updates = await self.bot.get_updates(
  File "C:\Users\Dmitry\AppData\Local\Programs\Python\Python39\lib\site-packages\aiogram\bot\bot.py", line 110, in get_updates
    result = await self.request(api.Methods.GET_UPDATES, payload)
  File "C:\Users\Dmitry\AppData\Local\Programs\Python\Python39\lib\site-packages\aiogram\bot\base.py", line 236, in request
    return await api.make_request(await self.get_session(), self.server, self.__token, method, data, files,
  File "C:\Users\Dmitry\AppData\Local\Programs\Python\Python39\lib\site-packages\aiogram\bot\api.py", line 140, in make_request
    return check_result(method, response.content_type, response.status, await response.text())
  File "C:\Users\Dmitry\AppData\Local\Programs\Python\Python39\lib\site-packages\aiogram\bot\api.py", line 119, in check_result
    exceptions.ConflictError.detect(description)
  File "C:\Users\Dmitry\AppData\Local\Programs\Python\Python39\lib\site-packages\aiogram\utils\exceptions.py", line 140, in detect
    raise err(cls.text or description)
aiogram.utils.exceptions.TerminatedByOtherGetUpdates: Terminated by other getupdates request; make sure that only one bot instance is running
