2023-11-03 18:29:23,033 - rabotakazank - INFO - SUCCESS CONNECTION BOT rabotakazank
2023-11-03 18:34:12,156 - rabotakazank - INFO - SUCCESS CONNECTION BOT rabotakazank
2023-11-03 18:50:56,287 - asyncio - ERROR - Task exception was never retrieved
future: <Task finished name='Task-27' coro=<Dispatcher._process_polling_updates() done, defined at C:\Users\Dmitry\AppData\Local\Programs\Python\Python39\lib\site-packages\aiogram\dispatcher\dispatcher.py:407> exception=MissingSchema("Invalid URL 'https:/vk.com/photo-22156807_457244649': No schema supplied. Perhaps you meant http://https:/vk.com/photo-22156807_457244649?")>
Traceback (most recent call last):
  File "C:\Users\Dmitry\AppData\Local\Programs\Python\Python39\lib\site-packages\aiogram\dispatcher\dispatcher.py", line 415, in _process_polling_updates
    for responses in itertools.chain.from_iterable(await self.process_updates(updates, fast)):
  File "C:\Users\Dmitry\AppData\Local\Programs\Python\Python39\lib\site-packages\aiogram\dispatcher\dispatcher.py", line 235, in process_updates
    return await asyncio.gather(*tasks)
  File "C:\Users\Dmitry\AppData\Local\Programs\Python\Python39\lib\site-packages\aiogram\dispatcher\handler.py", line 117, in notify
    response = await handler_obj.handler(*args, **partial_data)
  File "C:\Users\Dmitry\AppData\Local\Programs\Python\Python39\lib\site-packages\aiogram\dispatcher\dispatcher.py", line 256, in process_update
    return await self.message_handlers.notify(update.message)
  File "C:\Users\Dmitry\AppData\Local\Programs\Python\Python39\lib\site-packages\aiogram\dispatcher\handler.py", line 117, in notify
    response = await handler_obj.handler(*args, **partial_data)
  File "c:\Users\Dmitry\Documents\Git\new_groups\helper_bot\handlers\group_handlers\delay\handlers\handlers.py", line 173, in editing_default_photo
    if group.set_default_photo(message.text):
  File "c:\Users\Dmitry\Documents\Git\new_groups\helper_bot\group\modules\delay\delay.py", line 32, in set_default_photo
    response = requests.get(url=f"https:/vk.com/{photo}")
  File "C:\Users\Dmitry\AppData\Local\Programs\Python\Python39\lib\site-packages\requests\api.py", line 75, in get
    return request('get', url, params=params, **kwargs)
  File "C:\Users\Dmitry\AppData\Local\Programs\Python\Python39\lib\site-packages\requests\api.py", line 61, in request
    return session.request(method=method, url=url, **kwargs)
  File "C:\Users\Dmitry\AppData\Local\Programs\Python\Python39\lib\site-packages\requests\sessions.py", line 528, in request
    prep = self.prepare_request(req)
  File "C:\Users\Dmitry\AppData\Local\Programs\Python\Python39\lib\site-packages\requests\sessions.py", line 456, in prepare_request
    p.prepare(
  File "C:\Users\Dmitry\AppData\Local\Programs\Python\Python39\lib\site-packages\requests\models.py", line 316, in prepare
    self.prepare_url(url, params)
  File "C:\Users\Dmitry\AppData\Local\Programs\Python\Python39\lib\site-packages\requests\models.py", line 390, in prepare_url
    raise MissingSchema(error)
requests.exceptions.MissingSchema: Invalid URL 'https:/vk.com/photo-22156807_457244649': No schema supplied. Perhaps you meant http://https:/vk.com/photo-22156807_457244649?
2023-11-03 19:14:39,071 - asyncio - ERROR - Task exception was never retrieved
future: <Task finished name='Task-37' coro=<Dispatcher._process_polling_updates() done, defined at C:\Users\Dmitry\AppData\Local\Programs\Python\Python39\lib\site-packages\aiogram\dispatcher\dispatcher.py:407> exception=AttributeError("'Group' object has no attribute 'set_logger'")>
Traceback (most recent call last):
  File "C:\Users\Dmitry\AppData\Local\Programs\Python\Python39\lib\site-packages\aiogram\dispatcher\dispatcher.py", line 415, in _process_polling_updates
    for responses in itertools.chain.from_iterable(await self.process_updates(updates, fast)):
  File "C:\Users\Dmitry\AppData\Local\Programs\Python\Python39\lib\site-packages\aiogram\dispatcher\dispatcher.py", line 235, in process_updates
    return await asyncio.gather(*tasks)
  File "C:\Users\Dmitry\AppData\Local\Programs\Python\Python39\lib\site-packages\aiogram\dispatcher\handler.py", line 117, in notify
    response = await handler_obj.handler(*args, **partial_data)
  File "C:\Users\Dmitry\AppData\Local\Programs\Python\Python39\lib\site-packages\aiogram\dispatcher\dispatcher.py", line 256, in process_update
    return await self.message_handlers.notify(update.message)
  File "C:\Users\Dmitry\AppData\Local\Programs\Python\Python39\lib\site-packages\aiogram\dispatcher\handler.py", line 117, in notify
    response = await handler_obj.handler(*args, **partial_data)
  File "c:\Users\Dmitry\Documents\Git\new_groups\helper_bot\handlers\addind_group\handlers\handlers.py", line 83, in adding_vk_admin
    group.set_logger(message.bot)
AttributeError: 'Group' object has no attribute 'set_logger'
