2023-11-05 16:35:44,796 - asyncio - ERROR - Task exception was never retrieved
future: <Task finished name='Task-14' coro=<Dispatcher._process_polling_updates() done, defined at C:\Users\Dmitry\AppData\Local\Programs\Python\Python39\lib\site-packages\aiogram\dispatcher\dispatcher.py:407> exception=IntegrityError('datatype mismatch')>
Traceback (most recent call last):
  File "C:\Users\Dmitry\AppData\Local\Programs\Python\Python39\lib\site-packages\aiogram\dispatcher\dispatcher.py", line 415, in _process_polling_updates
    for responses in itertools.chain.from_iterable(await self.process_updates(updates, fast)):
  File "C:\Users\Dmitry\AppData\Local\Programs\Python\Python39\lib\site-packages\aiogram\dispatcher\dispatcher.py", line 235, in process_updates
    return await asyncio.gather(*tasks)
  File "C:\Users\Dmitry\AppData\Local\Programs\Python\Python39\lib\site-packages\aiogram\dispatcher\handler.py", line 117, in notify
    response = await handler_obj.handler(*args, **partial_data)
  File "C:\Users\Dmitry\AppData\Local\Programs\Python\Python39\lib\site-packages\aiogram\dispatcher\dispatcher.py", line 256, in process_update
    return await self.message_handlers.notify(update.message)
  File "C:\Users\Dmitry\AppData\Local\Programs\Python\Python39\lib\site-packages\aiogram\dispatcher\handler.py", line 117, in notify
    response = await handler_obj.handler(*args, **partial_data)
  File "c:\Users\Dmitry\Documents\Git\groups\helper_bot\handlers\main_handlers.py", line 41, in adding_user
    add_tg_user(message.text)
  File "c:\Users\Dmitry\Documents\Git\groups\database\sql.py", line 63, in add_tg_user
    cursor.execute(query, (user_id,))
sqlite3.IntegrityError: datatype mismatch
